Traceback (most recent call last):
  File "<frozen runpy>", line 198, in _run_module_as_main
  File "<frozen runpy>", line 88, in _run_code
  File "/root/data-tmp/dl/src/rnn/train_surname_classification.py", line 30, in <module>
    from .models.baseline import RNN as ManualRNN  # 原始手动实现的RNN
    ^^^^^^^^^^^^^^^^^^^^^^^^^^^^^^^^^^^^^^^^^^^^^
  File "/root/data-tmp/dl/src/rnn/models/__init__.py", line 1, in <module>
    from .baseline import BaselineLSTM
ImportError: cannot import name 'BaselineLSTM' from 'src.rnn.models.baseline' (/root/data-tmp/dl/src/rnn/models/baseline.py)
Traceback (most recent call last):
  File "<frozen runpy>", line 198, in _run_module_as_main
  File "<frozen runpy>", line 88, in _run_code
  File "/root/data-tmp/dl/src/rnn/train_surname_classification.py", line 30, in <module>
    from .models.baseline import RNN as ManualRNN  # 原始手动实现的RNN
    ^^^^^^^^^^^^^^^^^^^^^^^^^^^^^^^^^^^^^^^^^^^^^
  File "/root/data-tmp/dl/src/rnn/models/__init__.py", line 1, in <module>
    from .baseline import BaselineLSTM
ImportError: cannot import name 'BaselineLSTM' from 'src.rnn.models.baseline' (/root/data-tmp/dl/src/rnn/models/baseline.py)
Traceback (most recent call last):
  File "<frozen runpy>", line 198, in _run_module_as_main
  File "<frozen runpy>", line 88, in _run_code
  File "/root/data-tmp/dl/src/rnn/train_surname_classification.py", line 30, in <module>
    from .models.baseline import RNN as ManualRNN  # 原始手动实现的RNN
    ^^^^^^^^^^^^^^^^^^^^^^^^^^^^^^^^^^^^^^^^^^^^^
  File "/root/data-tmp/dl/src/rnn/models/__init__.py", line 1, in <module>
    from .baseline import BaselineLSTM
ImportError: cannot import name 'BaselineLSTM' from 'src.rnn.models.baseline' (/root/data-tmp/dl/src/rnn/models/baseline.py)
Traceback (most recent call last):
  File "<frozen runpy>", line 198, in _run_module_as_main
  File "<frozen runpy>", line 88, in _run_code
  File "/root/data-tmp/dl/src/rnn/train_surname_classification.py", line 30, in <module>
    from .models.baseline import RNN as ManualRNN  # 原始手动实现的RNN
    ^^^^^^^^^^^^^^^^^^^^^^^^^^^^^^^^^^^^^^^^^^^^^
  File "/root/data-tmp/dl/src/rnn/models/__init__.py", line 1, in <module>
    from .baseline import BaselineLSTM
ImportError: cannot import name 'BaselineLSTM' from 'src.rnn.models.baseline' (/root/data-tmp/dl/src/rnn/models/baseline.py)
Traceback (most recent call last):
  File "<frozen runpy>", line 198, in _run_module_as_main
  File "<frozen runpy>", line 88, in _run_code
  File "/root/data-tmp/dl/src/rnn/train_surname_classification.py", line 30, in <module>
    from .models.baseline import RNN as ManualRNN  # 原始手动实现的RNN
    ^^^^^^^^^^^^^^^^^^^^^^^^^^^^^^^^^^^^^^^^^^^^^
  File "/root/data-tmp/dl/src/rnn/models/__init__.py", line 1, in <module>
    from .baseline import BaselineLSTM
ImportError: cannot import name 'BaselineLSTM' from 'src.rnn.models.baseline' (/root/data-tmp/dl/src/rnn/models/baseline.py)
Traceback (most recent call last):
  File "<frozen runpy>", line 198, in _run_module_as_main
  File "<frozen runpy>", line 88, in _run_code
  File "/root/data-tmp/dl/src/rnn/train_surname_classification.py", line 30, in <module>
    from .models.baseline import RNN as ManualRNN  # 原始手动实现的RNN
    ^^^^^^^^^^^^^^^^^^^^^^^^^^^^^^^^^^^^^^^^^^^^^
  File "/root/data-tmp/dl/src/rnn/models/__init__.py", line 1, in <module>
    from .baseline import BaselineLSTM
ImportError: cannot import name 'BaselineLSTM' from 'src.rnn.models.baseline' (/root/data-tmp/dl/src/rnn/models/baseline.py)
Traceback (most recent call last):
  File "<frozen runpy>", line 198, in _run_module_as_main
  File "<frozen runpy>", line 88, in _run_code
  File "/root/data-tmp/dl/src/rnn/train_surname_classification.py", line 30, in <module>
    from .models.baseline import RNN as ManualRNN  # 原始手动实现的RNN
    ^^^^^^^^^^^^^^^^^^^^^^^^^^^^^^^^^^^^^^^^^^^^^
  File "/root/data-tmp/dl/src/rnn/models/__init__.py", line 1, in <module>
    from .baseline import BaselineLSTM
ImportError: cannot import name 'BaselineLSTM' from 'src.rnn.models.baseline' (/root/data-tmp/dl/src/rnn/models/baseline.py)
W0618 00:27:28.766000 527871 site-packages/torch/distributed/elastic/multiprocessing/api.py:900] Sending process 527919 closing signal SIGTERM
W0618 00:27:28.768000 527871 site-packages/torch/distributed/elastic/multiprocessing/api.py:900] Sending process 527920 closing signal SIGTERM
W0618 00:27:28.770000 527871 site-packages/torch/distributed/elastic/multiprocessing/api.py:900] Sending process 527923 closing signal SIGTERM
W0618 00:27:28.772000 527871 site-packages/torch/distributed/elastic/multiprocessing/api.py:900] Sending process 527924 closing signal SIGTERM
W0618 00:27:28.773000 527871 site-packages/torch/distributed/elastic/multiprocessing/api.py:900] Sending process 527925 closing signal SIGTERM
E0618 00:27:28.839000 527871 site-packages/torch/distributed/elastic/multiprocessing/api.py:874] failed (exitcode: 1) local_rank: 2 (pid: 527921) of binary: /root/data-tmp/miniconda3/envs/llm/bin/python3.12
Traceback (most recent call last):
  File "/root/data-tmp/miniconda3/envs/llm/bin/torchrun", line 8, in <module>
    sys.exit(main())
             ^^^^^^
  File "/root/data-tmp/miniconda3/envs/llm/lib/python3.12/site-packages/torch/distributed/elastic/multiprocessing/errors/__init__.py", line 355, in wrapper
    return f(*args, **kwargs)
           ^^^^^^^^^^^^^^^^^^
  File "/root/data-tmp/miniconda3/envs/llm/lib/python3.12/site-packages/torch/distributed/run.py", line 892, in main
    run(args)
  File "/root/data-tmp/miniconda3/envs/llm/lib/python3.12/site-packages/torch/distributed/run.py", line 883, in run
    elastic_launch(
  File "/root/data-tmp/miniconda3/envs/llm/lib/python3.12/site-packages/torch/distributed/launcher/api.py", line 139, in __call__
    return launch_agent(self._config, self._entrypoint, list(args))
           ^^^^^^^^^^^^^^^^^^^^^^^^^^^^^^^^^^^^^^^^^^^^^^^^^^^^^^^^
  File "/root/data-tmp/miniconda3/envs/llm/lib/python3.12/site-packages/torch/distributed/launcher/api.py", line 270, in launch_agent
    raise ChildFailedError(
torch.distributed.elastic.multiprocessing.errors.ChildFailedError: 
============================================================
src.rnn.train_surname_classification FAILED
------------------------------------------------------------
Failures:
[1]:
  time      : 2025-06-18_00:27:28
  host      : container-0fed40a4f0-b0ff74cc
  rank      : 3 (local_rank: 3)
  exitcode  : 1 (pid: 527922)
  error_file: <N/A>
  traceback : To enable traceback see: https://pytorch.org/docs/stable/elastic/errors.html
------------------------------------------------------------
Root Cause (first observed failure):
[0]:
  time      : 2025-06-18_00:27:28
  host      : container-0fed40a4f0-b0ff74cc
  rank      : 2 (local_rank: 2)
  exitcode  : 1 (pid: 527921)
  error_file: <N/A>
  traceback : To enable traceback see: https://pytorch.org/docs/stable/elastic/errors.html
============================================================
